<?xml version="1.0" ?>
<robot name="ur7e" xmlns:xacro="http://ros.org/wiki/xacro">
  <xacro:include filename="$(find optical_platiform_description)/urdf/optical_platiform_description.urdf" />
  <xacro:include filename="$(find robot_arm_base_link)/urdf/robot_arm_base_link.urdf" />
  <xacro:include filename="$(find sensers_fixture_description)/urdf/sensers_fixture_description.urdf" />


  <link name="world"/>

  <joint name="table_to_world" type="fixed">
    <parent link="world"/>
    <child link="optical_platiform_base_link"/>
    <origin xyz="0.0 0.0 0.8" rpy="0 0 0"/>
  </joint>

  <link name="ground_plane">
    <visual>
      <origin rpy="0 0 0" xyz="0 0 0"/>
      <geometry>
        <box size="5 5 0.01"/>
      </geometry>
      <material name="ground_white">
        <color rgba="1 1 1 0.5"/>
      </material>
    </visual>
    <collision>
      <origin rpy="0 0 0" xyz="0 0 -0.005"/>
      <geometry>
        <box size="5 5 0.01"/>
      </geometry>
    </collision>
  </link>
  <joint name="ground_plane_joint" type="fixed">
    <origin rpy="0 0 0" xyz="0 0 -0.005"/>
    <parent link="world"/>
    <child link="ground_plane"/>
  </joint>

<!-- ros2_control开始地方 -->
  <ros2_control name="ur7e" type="system">
    <hardware>
      <plugin>gazebo_ros2_control/GazeboSystem</plugin>
      <plugin>mock_components/GenericSystem</plugin>
      <param name="fake_sensor_commands">False</param>
      <param name="state_following_offset">0.0</param>
      <param name="calculate_dynamics">true</param>
    </hardware>
    <joint name="shoulder_pan_joint">
      <command_interface name="position"/>
      <command_interface name="velocity"/>
      <command_interface name="effort"/>
      <state_interface name="position">
        <param name="initial_value">0.0</param>
      </state_interface>
      <state_interface name="velocity"/>
      <state_interface name="effort"/>
    </joint>
    <joint name="shoulder_lift_joint">
      <command_interface name="position"/>
      <command_interface name="velocity"/>
      <command_interface name="effort"/>
      <state_interface name="position">
        <param name="initial_value">-1.57</param>
      </state_interface>
      <state_interface name="velocity"/>
      <state_interface name="effort"/>
    </joint>
    <joint name="elbow_joint">
      <command_interface name="position"/>
      <command_interface name="velocity"/>
      <command_interface name="effort"/>
      <state_interface name="position">
        <param name="initial_value">0.0</param>
      </state_interface>
      <state_interface name="velocity"/>
      <state_interface name="effort"/>
    </joint>
    <joint name="wrist_1_joint">
      <command_interface name="position"/>
      <command_interface name="velocity"/>
      <command_interface name="effort"/>
      <state_interface name="position">
        <param name="initial_value">-1.57</param>
      </state_interface>
      <state_interface name="velocity"/>
      <state_interface name="effort"/>
    </joint>
    <joint name="wrist_2_joint">
      <command_interface name="position"/>
      <command_interface name="velocity"/>
      <command_interface name="effort"/>
      <state_interface name="position">
        <param name="initial_value">0.0</param>
      </state_interface>
      <state_interface name="velocity"/>
      <state_interface name="effort"/>
    </joint>
    <joint name="wrist_3_joint">
      <command_interface name="position"/>
      <command_interface name="velocity"/>
      <command_interface name="effort"/>
      <state_interface name="position">
        <param name="initial_value">0.0</param>
      </state_interface>
      <state_interface name="velocity"/>
      <state_interface name="effort"/>
    </joint>

    <joint name="ft300_sensor_joint">
      <state_interface name="position">
        <param name="initial_value">0.0</param>
      </state_interface>
    </joint>
  </ros2_control>


<!-- ros2_control结束地方 -->

  <link name="base_link"/>
  <link name="base_link_inertia">
    <visual>
      <origin rpy="0 0 3.141592653589793" xyz="0 0 0"/>
      <geometry>
         <mesh filename="file:///opt/ros/humble/share/ur_description/meshes/ur5e/visual/base.dae"/>
      </geometry>
    </visual>
    <collision>
      <origin rpy="0 0 3.141592653589793" xyz="0 0 0"/>
      <geometry>
        <mesh filename="file:///opt/ros/humble/share/ur_description/meshes/ur5e/collision/base.stl"/>
      </geometry>
    </collision>
    <inertial>
      <mass value="4.0"/>
      <origin rpy="0 0 0" xyz="0 0 0"/>
      <inertia ixx="0.00443333156" ixy="0.0" ixz="0.0" iyy="0.00443333156" iyz="0.0" izz="0.0072"/>
    </inertial>
  </link>
  <link name="shoulder_link">
    <visual>
      <origin rpy="0 0 3.141592653589793" xyz="0 0 0"/>
      <geometry>
        <mesh filename="file:///opt/ros/humble/share/ur_description/meshes/ur5e/visual/shoulder.dae"/>
      </geometry>
    </visual>
    <collision>
      <origin rpy="0 0 3.141592653589793" xyz="0 0 0"/>
      <geometry>
        <mesh filename="file:///opt/ros/humble/share/ur_description/meshes/ur5e/collision/shoulder.stl"/>
      </geometry>
    </collision>
    <inertial>
      <mass value="3.761"/>
      <origin rpy="1.570796326794897 0 0" xyz="0.0 -0.00193 -0.02561"/>
      <inertia ixx="0.0070021" ixy="7.3e-07" ixz="-1.053e-05" iyy="0.00648091" iyz="0.00049994" izz="0.00657286"/>
    </inertial>
  </link>
  <link name="upper_arm_link">
    <visual>
      <origin rpy="1.5707963267948966 0 -1.5707963267948966" xyz="0 0 0.138"/>
      <geometry>
        <mesh filename="file:///opt/ros/humble/share/ur_description/meshes/ur5e/visual/upperarm.dae"/>
      </geometry>
    </visual>
    <collision>
      <origin rpy="1.5707963267948966 0 -1.5707963267948966" xyz="0 0 0.138"/>
      <geometry>
        <mesh filename="file:///opt/ros/humble/share/ur_description/meshes/ur5e/collision/upperarm.stl"/>
      </geometry>
    </collision>
    <inertial>
      <mass value="8.058"/>
      <origin rpy="0 0 0" xyz="-0.2125 0.0 0.11336"/>
      <inertia ixx="0.01505885" ixy="-5.4e-05" ixz="5.63e-06" iyy="0.33388086" iyz="-1.81e-06" izz="0.33247207"/>
    </inertial>
  </link>
  <link name="forearm_link">
    <visual>
      <origin rpy="1.5707963267948966 0 -1.5707963267948966" xyz="0 0 0.007"/>
      <geometry>
        <mesh filename="file:///opt/ros/humble/share/ur_description/meshes/ur5e/visual/forearm.dae"/>
      </geometry>
    </visual>
    <collision>
       <origin rpy="1.5707963267948966 0 -1.5707963267948966" xyz="0 0 0.007"/>
      <geometry>
        <mesh filename="file:///opt/ros/humble/share/ur_description/meshes/ur5e/collision/forearm.stl"/>
      </geometry>
    </collision>
    <inertial>
      <mass value="2.846"/>
      <origin rpy="0 0 0" xyz="-0.2422 0.0 0.0265"/>
      <inertia ixx="0.00399632" ixy="-1.365e-05" ixz="0.00137272" iyy="0.07879254" iyz="-6.6e-06" izz="0.0784851"/>
    </inertial>
  </link>
  <link name="wrist_1_link">
    <visual>
      <origin rpy="1.5707963267948966 0 0" xyz="0 0 -0.127"/>
      <geometry>
        <mesh filename="file:///opt/ros/humble/share/ur_description/meshes/ur5e/visual/wrist1.dae"/>
      </geometry>
    </visual>
    <collision>
      <origin rpy="1.5707963267948966 0 0" xyz="0 0 -0.127"/>
      <geometry>
        <mesh filename="file:///opt/ros/humble/share/ur_description/meshes/ur5e/collision/wrist1.stl"/>
      </geometry>
    </collision>
    <inertial>
      <mass value="1.37"/>
      <origin rpy="1.570796326794897 0 0" xyz="0.0 -0.01634 -0.0018"/>
      <inertia ixx="0.00165491" ixy="-2.82e-06" ixz="-4.38e-06" iyy="0.00135962" iyz="0.00010157" izz="0.00126279"/>
    </inertial>
  </link>
  <link name="wrist_2_link">
    <visual>
      <origin rpy="0 0 0" xyz="0 0 -0.0997"/>
      <geometry>
        <mesh filename="file:///opt/ros/humble/share/ur_description/meshes/ur5e/visual/wrist2.dae"/>
      </geometry>
    </visual>
    <collision>
      <origin rpy="0 0 0" xyz="0 0 -0.0997"/>
      <geometry>
        <mesh filename="file:///opt/ros/humble/share/ur_description/meshes/ur5e/collision/wrist2.stl"/>
      </geometry>
    </collision>
    <inertial>
      <mass value="1.3"/>
      <origin rpy="-1.570796326794897 0 0" xyz="0.0 0.01634 -0.0018"/>
      <inertia ixx="0.00135617" ixy="-2.74e-06" ixz="4.44e-06" iyy="0.00127827" iyz="-5.048e-05" izz="0.00096614"/>
    </inertial>
  </link>
  <link name="wrist_3_link">
    <visual>
      <origin rpy="1.5707963267948966 0 0" xyz="0 0 -0.0989"/>
      <geometry>
        <mesh filename="file:///opt/ros/humble/share/ur_description/meshes/ur5e/visual/wrist3.dae"/>
      </geometry>
    </visual>
    <collision>
      <origin rpy="1.5707963267948966 0 0" xyz="0 0 -0.0989"/>
      <geometry>
        <mesh filename="file:///opt/ros/humble/share/ur_description/meshes/ur5e/collision/wrist3.stl"/>
      </geometry>
    </collision>
    <inertial>
      <mass value="0.365"/>
      <origin rpy="0 0 0" xyz="0.0 0.0 -0.001159"/>
      <inertia ixx="0.00018694" ixy="6e-08" ixz="-1.7e-07" iyy="0.00018908" iyz="-9.2e-07" izz="0.00025756"/>
    </inertial>
  </link>

  <joint name="base_to_table" type="fixed">
    <parent link="optical_platiform_base_link"/>
    <child link="robot_arm_base_link"/>
    <origin xyz="-0.325 -0.625 0.0" rpy="0 0 0"/>
  </joint>
  <joint name="base_joint" type="fixed">
    <parent link="robot_arm_base_link"/>
    <child link="base_link"/>
    <origin xyz="-0.0 0.0 0.025" rpy="0 0 0"/>
  </joint>
  <joint name="base_link-base_link_inertia" type="fixed">
    <parent link="base_link"/>
    <child link="base_link_inertia"/>
    <origin rpy="0 0 3.141592653589793" xyz="0 0 0"/>
  </joint>
  <joint name="shoulder_pan_joint" type="revolute">
    <parent link="base_link_inertia"/>
    <child link="shoulder_link"/>
    <origin rpy="0 0 0" xyz="0 0 0.1625"/>
    <axis xyz="0 0 1"/>
    <limit effort="150.0" lower="-6.283185307179586" upper="6.283185307179586" velocity="3.141592653589793"/>
    <dynamics damping="0" friction="0"/>
  </joint>
  <joint name="shoulder_lift_joint" type="revolute">
    <parent link="shoulder_link"/>
    <child link="upper_arm_link"/>
    <origin rpy="1.570796327 0 0" xyz="0 0 0"/>
    <axis xyz="0 0 1"/>
    <limit effort="150.0" lower="-6.283185307179586" upper="6.283185307179586" velocity="3.141592653589793"/>
    <dynamics damping="0" friction="0"/>
  </joint>
  <joint name="elbow_joint" type="revolute">
    <parent link="upper_arm_link"/>
    <child link="forearm_link"/>
    <origin rpy="0 0 0" xyz="-0.425 0 0"/>
    <axis xyz="0 0 1"/>
    <limit effort="150.0" lower="-3.141592653589793" upper="3.141592653589793" velocity="3.141592653589793"/>
    <dynamics damping="0" friction="0"/>
  </joint>
  <joint name="wrist_1_joint" type="revolute">
    <parent link="forearm_link"/>
    <child link="wrist_1_link"/>
    <origin rpy="0 0 0" xyz="-0.3922 0 0.1333"/>
    <axis xyz="0 0 1"/>
    <limit effort="28.0" lower="-6.283185307179586" upper="6.283185307179586" velocity="3.141592653589793"/>
    <dynamics damping="0" friction="0"/>
  </joint>
  <joint name="wrist_2_joint" type="revolute">
    <parent link="wrist_1_link"/>
    <child link="wrist_2_link"/>
    <origin rpy="1.570796327 0 0" xyz="0 -0.0997 -2.044881182297852e-11"/>
    <axis xyz="0 0 1"/>
    <limit effort="28.0" lower="-6.283185307179586" upper="6.283185307179586" velocity="3.141592653589793"/>
    <dynamics damping="0" friction="0"/>
  </joint>
  <joint name="wrist_3_joint" type="revolute">
    <parent link="wrist_2_link"/>
    <child link="wrist_3_link"/>
    <origin rpy="1.570796326589793 3.141592653589793 3.141592653589793" xyz="0 0.0996 -2.042830148012698e-11"/>
    <axis xyz="0 0 1"/>
    <limit effort="28.0" lower="-6.283185307179586" upper="6.283185307179586" velocity="3.141592653589793"/>
    <dynamics damping="0" friction="0"/>
  </joint>
  
  <link name="ft_frame"/>
  <joint name="wrist_3_link-ft_frame" type="fixed">
    <parent link="wrist_3_link"/>
    <child link="ft_frame"/>
    <origin rpy="3.141592653589793 0 0" xyz="0 0 0"/>
  </joint>
  
  <link name="base"/>
  <joint name="base_link-base_fixed_joint" type="fixed">
    <origin rpy="0 0 3.141592653589793" xyz="0 0 0"/>
    <parent link="base_link"/>
    <child link="base"/>
  </joint>


  <link name="flange"/>
  <joint name="wrist_3-flange" type="fixed">
    <parent link="wrist_3_link"/>
    <child link="flange"/>
    <origin rpy="0 -1.5707963267948966 -1.5707963267948966" xyz="0 0 0"/>
  </joint>
  <link name="tool0"/>
  <joint name="flange-tool0" type="fixed">
    <origin rpy="1.5707963267948966 0 1.5707963267948966" xyz="0 0 0"/>
    <parent link="flange"/>
    <child link="tool0"/>
  </joint>

  <joint name="ft300_fix" type="fixed">
    <origin rpy="0 0 0" xyz="0 0 0"/>
    <parent link="tool0"/>
    <child link="ft300_mounting_plate"/>
  </joint>
  <link name="ft300_mounting_plate">
    <visual>
      <origin rpy="0 0 0" xyz="0 0 0"/>
      <geometry>
        <mesh filename="file:///home/lk/ur_sim/install/mybot_description/share/mybot_description/meshes/visual/mountings/robotiq_ft300-G-062-COUPLING_G-50-4M6-1D6_20181119.STL"/>
      </geometry>
      <material name="Robotiq-Grey">
        <color rgba="0.4 0.4 0.4 1.0"/>
      </material>
    </visual>
    <collision>
      <origin rpy="0 0 0" xyz="0 0 0"/>
      <geometry>
        <mesh filename="file:///home/lk/ur_sim/install/mybot_description/share/mybot_description/meshes/collision/mountings/robotiq_ft300-G-062-COUPLING_G-50-4M6-1D6_20181119.STL"/>
      </geometry>
    </collision>
  </link>

  <joint name="ft300_mounting_plate_joint" type="fixed">
    <origin rpy="0 3.141592653589793 0" xyz="0 0 0.0415"/>
    <parent link="ft300_mounting_plate"/>
    <child link="ft300_sensor"/>
  </joint>
  <link name="ft300_sensor">
    <inertial>
      <origin rpy="0 0 0" xyz="0 0 -0.017"/>
      <mass value="0.300"/>
      <inertia ixx="0.000262" ixy="0" ixz="1e-06" iyx="0" iyy="0.000265" iyz="1e-06" izx="-1e-06" izy="1e-06" izz="0.000219"/>
    </inertial>
    <visual>
      <origin rpy="0 0 0" xyz="0 0 0"/>
      <geometry>
        <mesh filename="file:///home/lk/ur_sim/install/mybot_description/share/mybot_description/meshes/visual/robotiq_ft300.STL"/>
      </geometry>
      <material name="Robotiq-Black">
        <color rgba="0.2 0.2 0.2 1.0"/>
      </material>
    </visual>
    <collision>
      <origin rpy="0 0 0" xyz="0 0 0"/>
      <geometry>
        <mesh filename="file:///home/lk/ur_sim/install/mybot_description/share/mybot_description/meshes/collision/robotiq_ft300.STL"/>
      </geometry>
    </collision>
  </link>

  <joint name="measurment_joint" type="fixed">
    <origin rpy="0 3.141592653589793 -1.5707963267948966" xyz="0 0 0"/>
    <parent link="ft300_sensor"/>
    <child link="robotiq_ft_frame_id"/>
  </joint>
  <link name="robotiq_ft_frame_id"/>


  <link name="force_transfer_link">
    <inertial>
      <origin rpy="0 0 0" xyz="0 0 0"/>
      <mass value="0.01"/> <inertia ixx="1e-6" ixy="0.0" ixz="0.0" iyy="1e-6" iyz="0.0" izz="1e-6"/>
    </inertial>
  </link>

  <joint name="ft300_sensor_joint" type="revolute">
    <origin rpy="0 3.141592653589793 -1.5707963267948966" xyz="0 0 0"/>
    <parent link="ft300_sensor"/>
    <child link="force_transfer_link"/> <axis xyz="0 0 1"/>
    <limit lower="0.0" upper="0.0" effort="1000.0" velocity="0.0"/>
  </joint>

  <joint name="fixture_joint" type="fixed">
    <parent link="force_transfer_link"/> 
    <child link="sensers_fixture"/>
    <origin xyz="0.0 0.0 0.0" rpy="1.5707963267948966 0 0"/>
  </joint>


  <gazebo reference="ft300_sensor">
    <material>Gazebo/DarkGrey</material>
  </gazebo>
  <gazebo reference="ft300_mounting_plate">
    <material>Gazebo/Gray</material>
  </gazebo>

  <gazebo reference="ft300_sensor_joint">
    <provideFeedback>true</provideFeedback>
  </gazebo>
  
  <gazebo>
    <plugin filename="libgazebo_ros_ft_sensor.so" name="gazebo_ros_ft_sensor">
      <ros>
        <namespace>/robotiq_ft300</namespace>
        <remapping>wrench:=ft_sensor_wrench</remapping>
      </ros>
      <joint_name>ft300_sensor_joint</joint_name>
      <update_rate>50.0</update_rate>
      <gaussian_noise>0.01</gaussian_noise>
    </plugin>
  </gazebo>

  <gazebo reference="world">
  </gazebo>
  
  <gazebo>
    <plugin filename="libgazebo_ros2_control.so" name="gazebo_ros2_control">  
      <parameters>/home/lk/ur_sim/src/ur7e_moveit_config/config/ros2_controllers.yaml</parameters>
      <robot_param_node>robot_state_publisher</robot_param_node>
      <robotParam>robot_description</robotParam>
    </plugin>
  </gazebo>

  <xacro:include filename="$(find realsense2_description)/urdf/_d435i.urdf.xacro" />
  <xacro:sensor_d435i parent="world" name="camera" use_nominal_extrinsics="true">
      <origin xyz="0.4 0 2.2" rpy="0 1.5708 0"/> 
  </xacro:sensor_d435i>

  <gazebo reference="camera_link">
      <sensor type="depth" name="d435i_depth_sensor">
          <always_on>true</always_on>
          <update_rate>30.0</update_rate>
          <camera name="camera">
            <horizontal_fov>1.5184</horizontal_fov>
              <image>
                  <width>640</width>
                  <height>480</height>
                  <format>R8G8B8</format>
              </image>
              <clip>
                  <near>0.1</near>
                  <far>2.0</far> 
              </clip>
            <depth_camera>
                <image>
                    <width>640</width>
                    <height>480</height>
                    <format>R8G8B8</format>
                </image>
                <clip>
                    <near>0.1</near>
                    <far>2.0</far>
                </clip>
            </depth_camera>              
          </camera>
          <plugin name="camera_plugin" filename="libgazebo_ros_camera.so">
              <ros>
                  <remapping>/camera/image_raw:=/camera/camera/color/image_raw</remapping>
                  <remapping>/camera/points:=/camera/camera/depth/color/points</remapping>
                  <remapping>/camera/depth/image_raw:=/camera/camera/depth/image_raw</remapping>
              </ros>
              <camera_name>camera</camera_name>
              <frame_name>camera_depth_optical_frame</frame_name>
              <min_depth>0.1</min_depth>
              <max_depth>2.0</max_depth>
          </plugin>
      </sensor>
  </gazebo>
</robot>